Workbook

Sheet Conduite
B2: Registre des habilitations : Conduite (CL ,CTR et CRMV) | J2: EPTC KENITRA
B4: L'habilitation est valable pour une durée supérieure à un mois. | C4: ✅ | D4: L'habilitation est valable pour une durée inférieure à un mois. | F4: ⚠️ | G4: L'habilitation est expirée. | H4: ⛔️
B6: Collaborateur | F6: La validité de l'habilitation | I6: Âge | M6: Périmètre d'habilitation | P6: Aptitude physique (VM) | U6: Aptitude psychologique | Z6: Aptitude Professionnelle
B7: Nom /Prénom | C7: Matricule | D7: Résidence | E7: Date d'autorisation | F7: Validité | G7: Date d'expiration | H7: Motif | I7: Date naissance | J7: Âge actuel | K7: Âge Fin 25 | L7: Âge Fin 26 | M7: Fonction | N7: Engin | O7: Ligne / Site | P7: Dernière VM | Q7: Résultat/Obs | R7: Âge_dernière VM | S7: Périodicité VM | T7: Date prochaine VM | U7: Dernier Psy | V7: Résultat/Obs | W7: Âge_dernier Psy | X7: Périodicité Psy | Y7: Date prochain Psy | Z7: Dernière évaluation | AA7: Résultat /Obs | AB7: Date prochaine évaluation | AC7: Colonne1 | AD7: Colonne2
B8: ABDELMALEK ABOUBAKR | C8: 42685P | D8: Kénitra | F8: =IF(Tableau3[[#This Row],[Date d''expiration ]]>TODAY()+31,"✅",IF(Tableau3[[#This Row],[Date d''expiration ]]> TODAY()+1, "⚠️","⛔️")) -> ✅ | G8: =MIN(T8,Y8,AB8) -> 46311 | H8: =IF( Tableau3[[#This Row],[Date d''expiration ]]>TODAY(),"Néant","Cas à justifier") -> Néant | I8: 31590 | J8: =YEARFRAC(I8,TODAY(),1) -> 40.195058 | K8: =YEARFRAC(I8,RG_DRH_S1_008!$E$4,1) -> 39.512663 | L8: =YEARFRAC(I8,RG_DRH_S1_008!$E$5,1) -> 40.512654 | M8: Conducteur de ligne | N8: E1450, E1400, E1300, E1250 | O8: Casa-Kenitra, Casa-Tanger , Casa-Marrakech, Fès - Casa | P8: 46197 | Q8: Apte classe 1 | R8: =YEARFRAC(I8,P8,1) -> 39.992454 | S8: =IF(L8<40,"4",IF(L8<50,"3",IF(L8<55,IF(Tableau3[[#This Row],[Fonction]]="Conducteur de ligne","2","3"),"1"))) -> 3 | T8: =EDATE(P8, (12*S8)) -> 47293 | U8: 45628 | V8: FAVORABLE MAINT | W8: =YEARFRAC(I8,U8,1) -> 38.433275 | X8: =IF(L8<40,"4",IF(L8<55,"3",IF(Tableau3[[#This Row],[Fonction]]="conducteur de ligne","1","2"))) -> 3 | Y8: =EDATE(U8, (12*X8)) -> 46723 | Z8: 45946 | AA8: =IF(Tableau3[[#This Row],[Date prochaine évaluation]]> TODAY(),"Réussi","Examen expiré") -> Réussi | AB8: =EDATE(Z8, 12) -> 46311 | AC8: =EDATE(AA8, 12) -> #VALUE!
B9: AFIF YASSINE | C9: 45395R | D9: Kénitra | F9: =IF(Tableau3[[#This Row],[Date d''expiration ]]>TODAY()+31,"✅",IF(Tableau3[[#This Row],[Date d''expiration ]]> TODAY()+1, "⚠️","⛔️")) -> ✅ | G9: =MIN(T9,Y9,AB9) -> 46494 | H9: =IF( Tableau3[[#This Row],[Date d''expiration ]]>TODAY(),"Néant","Cas à justifier") -> Néant | I9: 34164 | J9: =YEARFRAC(I9,TODAY(),1) -> 33.148494 | K9: =YEARFRAC(I9,RG_DRH_S1_008!$E$4,1) -> 32.466108 | L9: =YEARFRAC(I9,RG_DRH_S1_008!$E$5,1) -> 33.466098 | M9: Conducteur de ligne | N9: E1450, E1400 | O9: Casa-Kenitra, Casa-Tanger , Casa-Marrakech, Fès - Casa | P9: 45831 | Q9: Apte classe 1 | R9: =YEARFRAC(I9,P9,1) -> 31.943168 | S9: =IF(L9<40,"4",IF(L9<50,"3",IF(L9<55,IF(Tableau3[[#This Row],[Fonction]]="Conducteur de ligne","2","3"),"1"))) -> 4 | T9: =EDATE(P9, (12*S9)) -> 47292 | U9: 45033 | V9: FAVORABLE MAINT | W9: =YEARFRAC(I9,U9,1) -> 29.759671 | X9: =IF(L9<40,"4",IF(L9<55,"3",IF(Tableau3[[#This Row],[Fonction]]="conducteur de ligne","1","2"))) -> 4 | Y9: =EDATE(U9, (12*X9)) -> 46494 | Z9: 46206 | AA9: =IF(Tableau3[[#This Row],[Date prochaine évaluation]]> TODAY(),"Réussi","Examen expiré") -> Réussi | AB9: =EDATE(Z9, 12) -> 46571 | AC9: =EDATE(AA9, 12) -> #VALUE!
B10: ALIKY LAHCEN | C10: 42690X | D10: Kénitra | F10: =IF(Tableau3[[#This Row],[Date d''expiration ]]>TODAY()+31,"✅",IF(Tableau3[[#This Row],[Date d''expiration ]]> TODAY()+1, "⚠️","⛔️")) -> ✅ | G10: =MIN(T10,Y10,AB10) -> 46313 | H10: =IF( Tableau3[[#This Row],[Date d''expiration ]]>TODAY(),"Néant","Cas à justifier") -> Néant | I10: 30812 | J10: =YEARFRAC(I10,TODAY(),1) -> 42.323762 | K10: =YEARFRAC(I10,RG_DRH_S1_008!$E$4,1) -> 41.641353 | L10: =YEARFRAC(I10,RG_DRH_S1_008!$E$5,1) -> 42.641347 | M10: Conducteur de ligne | N10: Z2M, E1300, E1250, E1400, E1450 | O10: Casa-Kenitra, Casa-Tanger , Casa-Marrakech, Fès - Casa | P10: 46062 | Q10: Apte classe 1 | R10: =YEARFRAC(I10,P10,1) -> 41.75156 | S10: =IF(L10<40,"4",IF(L10<50,"3",IF(L10<55,IF(Tableau3[[#This Row],[Fonction]]="Conducteur de ligne","2","3"),"1"))) -> 3 | T10: =EDATE(P10, (12*S10)) -> 47158 | U10: 45379 | V10: FAVORABLE MAINT | W10: =YEARFRAC(I10,U10,1) -> 39.880275 | X10: =IF(L10<40,"4",IF(L10<55,"3",IF(Tableau3[[#This Row],[Fonction]]="conducteur de ligne","1","2"))) -> 3 | Y10: =EDATE(U10, (12*X10)) -> 46474 | Z10: 45948 | AA10: =IF(Tableau3[[#This Row],[Date prochaine évaluation]]> TODAY(),"Réussi","Examen expiré") -> Réussi | AB10: =EDATE(Z10, 12) -> 46313 | AC10: =EDATE(AA10, 12) -> #VALUE!
B11: ASDA NOUREDDINE | C11: 44775D | D11: Kénitra | F11: =IF(Tableau3[[#This Row],[Date d''expiration ]]>TODAY()+31,"✅",IF(Tableau3[[#This Row],[Date d''expiration ]]> TODAY()+1, "⚠️","⛔️")) -> ✅ | G11: =MIN(T11,Y11,AB11) -> 46482 | H11: =IF( Tableau3[[#This Row],[Date d''expiration ]]>TODAY(),"Néant","Cas à justifier") -> Néant | I11: 34183 | J11: =YEARFRAC(I11,TODAY(),1) -> 33.096473 | K11: =YEARFRAC(I11,RG_DRH_S1_008!$E$4,1) -> 32.414088 | L11: =YEARFRAC(I11,RG_DRH_S1_008!$E$5,1) -> 33.414076 | M11: Conducteur de ligne | N11: E1450, E1400, Z2M | O11: Fès - Casa, Casa-Kenitra, Casa-Tanger , Casa-Marrakech, Casa-Eljadida | P11: 45021 | Q11: Apte classe 1 | R11: =YEARFRAC(I11,P11,1) -> 29.674792 | S11: =IF(L11<40,"4",IF(L11<50,"3",IF(L11<55,IF(Tableau3[[#This Row],[Fonction]]="Conducteur de ligne","2","3"),"1"))) -> 4 | T11: =EDATE(P11, (12*S11)) -> 46482 | U11: 45982 | V11: FAVORABLE MAINT | W11: =YEARFRAC(I11,U11,1) -> 32.304571 | X11: =IF(L11<40,"4",IF(L11<55,"3",IF(Tableau3[[#This Row],[Fonction]]="conducteur de ligne","1","2"))) -> 4 | Y11: =EDATE(U11, (12*X11)) -> 47443 | Z11: 46145 | AA11: =IF(Tableau3[[#This Row],[Date prochaine évaluation]]> TODAY(),"Réussi","Examen expiré") -> Réussi | AB11: =EDATE(Z11, 12) -> 46510 | AC11: =EDATE(AA11, 12) -> #VALUE!
B12: AYATE OUTMANE | C12: 43692N | D12: Kénitra | F12: =IF(Tableau3[[#This Row],[Date d''expiration ]]>TODAY()+31,"✅",IF(Tableau3[[#This Row],[Date d''expiration ]]> TODAY()+1, "⚠️","⛔️")) -> ✅ | G12: =MIN(T12,Y12,AB12) -> 46343 | H12: =IF( Tableau3[[#This Row],[Date d''expiration ]]>TODAY(),"Néant","Cas à justifier") -> Néant | I12: 32263 | J12: =YEARFRAC(I12,TODAY(),1) -> 38.351141 | K12: =YEARFRAC(I12,RG_DRH_S1_008!$E$4,1) -> 37.668732 | L12: =YEARFRAC(I12,RG_DRH_S1_008!$E$5,1) -> 38.668726 | M12: Conducteur de ligne | N12: E1450, E1400, E1300, E1250 | O12: Casa-Kenitra, Casa-Tanger , Casa-Marrakech, Fès - Casa | P12: 45776 | Q12: Apte classe 1 | R12: =YEARFRAC(I12,P12,1) -> 36.995245 | S12: =IF(L12<40,"4",IF(L12<50,"3",IF(L12<55,IF(Tableau3[[#This Row],[Fonction]]="Conducteur de ligne","2","3"),"1"))) -> 4 | T12: =EDATE(P12, (12*S12)) -> 47237 | U12: 45775 | V12: FAVORABLE MAINT | W12: =YEARFRAC(I12,U12,1) -> 36.992507 | X12: =IF(L12<40,"4",IF(L12<55,"3",IF(Tableau3[[#This Row],[Fonction]]="conducteur de ligne","1","2"))) -> 4 | Y12: =EDATE(U12, (12*X12)) -> 47236 | Z12: 45978 | AA12: =IF(Tableau3[[#This Row],[Date prochaine évaluation]]> TODAY(),"Réussi","Examen expiré") -> Réussi | AB12: =EDATE(Z12, 12) -> 46343 | AC12: =EDATE(AA12, 12) -> #VALUE!
B13: AZEROUAL BRAHIM | C13: 44295G | D13: Kénitra | F13: =IF(Tableau3[[#This Row],[Date d''expiration ]]>TODAY()+31,"✅",IF(Tableau3[[#This Row],[Date d''expiration ]]> TODAY()+1, "⚠️","⛔️")) -> ✅ | G13: =MIN(T13,Y13,AB13) -> 46468 | H13: =IF( Tableau3[[#This Row],[Date d''expiration ]]>TODAY(),"Néant","Cas à justifier") -> Néant | I13: 33826 | J13: =YEARFRAC(I13,TODAY(),1) -> 34.071887 | K13: =YEARFRAC(I13,RG_DRH_S1_008!$E$4,1) -> 33.389484 | L13: =YEARFRAC(I13,RG_DRH_S1_008!$E$5,1) -> 34.389471 | M13: Conducteur de ligne | N13: E1450, E1400, Z2M | O13: Casa-Kenitra, Casa-Tanger , Casa-Marrakech, Fès - Casa | P13: 45167 | Q13: Apte classe 1 | R13: =YEARFRAC(I13,P13,1) -> 31.049966 | S13: =IF(L13<40,"4",IF(L13<50,"3",IF(L13<55,IF(Tableau3[[#This Row],[Fonction]]="Conducteur de ligne","2","3"),"1"))) -> 4 | T13: =EDATE(P13, (12*S13)) -> 46628 | U13: 45167 | V13: FAVORABLE MAINT | W13: =YEARFRAC(I13,U13,1) -> 31.049966 | X13: =IF(L13<40,"4",IF(L13<55,"3",IF(Tableau3[[#This Row],[Fonction]]="conducteur de ligne","1","2"))) -> 4 | Y13: =EDATE(U13, (12*X13)) -> 46628 | Z13: 46103 | AA13: =IF(Tableau3[[#This Row],[Date prochaine évaluation]]> TODAY(),"Réussi","Examen expiré") -> Réussi | AB13: =EDATE(Z13, 12) -> 46468 | AC13: =EDATE(AA13, 12) -> #VALUE!
B14: BELHAOUZI ALAE EDDINE | C14: 43417L | D14: Kénitra | F14: =IF(Tableau3[[#This Row],[Date d''expiration ]]>TODAY()+31,"✅",IF(Tableau3[[#This Row],[Date d''expiration ]]> TODAY()+1, "⚠️","⛔️")) -> ✅ | G14: =MIN(T14,Y14,AB14) -> 46336 | H14: =IF( Tableau3[[#This Row],[Date d''expiration ]]>TODAY(),"Néant","Cas à justifier") -> Néant | I14: 32487 | J14: =YEARFRAC(I14,TODAY(),1) -> 37.737873 | K14: =YEARFRAC(I14,RG_DRH_S1_008!$E$4,1) -> 37.055476 | L14: =YEARFRAC(I14,RG_DRH_S1_008!$E$5,1) -> 38.055458 | M14: Conducteur de ligne | N14: Z2M | O14: Casa-Kenitra | P14: 45845 | Q14: Apte classe 1 | R14: =YEARFRAC(I14,P14,1) -> 36.570893 | S14: =IF(L14<40,"4",IF(L14<50,"3",IF(L14<55,IF(Tableau3[[#This Row],[Fonction]]="Conducteur de ligne","2","3"),"1"))) -> 4 | T14: =EDATE(P14, (12*S14)) -> 47306 | U14: 45594 | V14: FAVORABLE MAINT | W14: =YEARFRAC(I14,U14,1) -> 35.883019 | X14: =IF(L14<40,"4",IF(L14<55,"3",IF(Tableau3[[#This Row],[Fonction]]="conducteur de ligne","1","2"))) -> 4 | Y14: =EDATE(U14, (12*X14)) -> 47055 | Z14: 45971 | AA14: =IF(Tableau3[[#This Row],[Date prochaine évaluation]]> TODAY(),"Réussi","Examen expiré") -> Réussi | AB14: =EDATE(Z14, 12) -> 46336 | AC14: =EDATE(AA14, 12) -> #VALUE!
B15: BENHIDA KHALIL | C15: 43992X | D15: Kénitra | F15: =IF(Tableau3[[#This Row],[Date d''expiration ]]>TODAY()+31,"✅",IF(Tableau3[[#This Row],[Date d''expiration ]]> TODAY()+1, "⚠️","⛔️")) -> ⛔️ | G15: =MIN(T15,Y15,AB15) -> 46038 | H15: ENCADRANT DE CONDUITE | I15: 33476 | J15: =YEARFRAC(I15,TODAY(),1) -> 35.030801 | K15: =YEARFRAC(I15,RG_DRH_S1_008!$E$4,1) -> 34.348404 | L15: =YEARFRAC(I15,RG_DRH_S1_008!$E$5,1) -> 35.348392 | M15: ENCADRANT DE CONDUITE | N15: Z2M, E1400, E1450 | O15: Casa-Kenitra, Casa-Tanger , Casa-Marrakech, Fès - Casa | P15: 45630 | Q15: Apte classe 1 | R15: =YEARFRAC(I15,P15,1) -> 33.274499 | S15: =IF(L15<40,"4",IF(L15<50,"3",IF(L15<55,IF(Tableau3[[#This Row],[Fonction]]="Conducteur de ligne","2","3"),"1"))) -> 4 | T15: =EDATE(P15, (12*S15)) -> 47091 | U15: 44966 | V15: FAVORABLE MAINT | W15: =YEARFRAC(I15,U15,1) -> 31.458558 | X15: =IF(L15<40,"4",IF(L15<55,"3",IF(Tableau3[[#This Row],[Fonction]]="conducteur de ligne","1","2"))) -> 4 | Y15: =EDATE(U15, (12*X15)) -> 46427 | Z15: 45673 | AA15: =IF(Tableau3[[#This Row],[Date prochaine évaluation]]> TODAY(),"Réussi","Examen expiré") -> Examen expiré | AB15: =EDATE(Z15, 12) -> 46038 | AC15: =EDATE(AA15, 12) -> #VALUE!
B16: BILOUL MOHAMED | C16: 45022Y | D16: Kénitra | F16: =IF(Tableau3[[#This Row],[Date d''expiration ]]>TODAY()+31,"✅",IF(Tableau3[[#This Row],[Date d''expiration ]]> TODAY()+1, "⚠️","⛔️")) -> ⛔️ | G16: =MIN(T16,Y16,AB16) -> 45742 | I16: 35023 | J16: =YEARFRAC(I16,TODAY(),1) -> 30.795346 | K16: =YEARFRAC(I16,RG_DRH_S1_008!$E$4,1) -> 30.112956 | L16: =YEARFRAC(I16,RG_DRH_S1_008!$E$5,1) -> 31.112936 | M16: Conducteur de ligne | N16: E1450, E1400 | O16: Casa-Kenitra, Casa-Tanger , Casa-Marrakech, Fès - Casa | P16: 45938 | Q16: Apte classe 1 | R16: =YEARFRAC(I16,P16,1) -> 29.882982 | S16: =IF(L16<40,"4",IF(L16<50,"3",IF(L16<55,IF(Tableau3[[#This Row],[Fonction]]="Conducteur de ligne","2","3"),"1"))) -> 4 | T16: =EDATE(P16, (12*S16)) -> 47399 | U16: 45938 | V16: FAVORABLE MAINT | W16: =YEARFRAC(I16,U16,1) -> 29.882982 | X16: =IF(L16<40,"4",IF(L16<55,"3",IF(Tableau3[[#This Row],[Fonction]]="conducteur de ligne","1","2"))) -> 4 | Y16: =EDATE(U16, (12*X16)) -> 47399 | Z16: 45377 | AA16: =IF(Tableau3[[#This Row],[Date prochaine évaluation]]> TODAY(),"Réussi","Examen expiré") -> Examen expiré | AB16: =EDATE(Z16, 12) -> 45742 | AC16: =EDATE(AA16, 12) -> #VALUE!
B17: BOUSSOUAR ANASS | C17: 45277B | D17: Kénitra | F17: =IF(Tableau3[[#This Row],[Date d''expiration ]]>TODAY()+31,"✅",IF(Tableau3[[#This Row],[Date d''expiration ]]> TODAY()+1, "⚠️","⛔️")) -> ⛔️ | G17: =MIN(T17,Y17,AB17) -> 46153 | H17: =IF( Tableau3[[#This Row],[Date d''expiration ]]>TODAY(),"Néant","Cas à justifier") -> Cas à justifier | I17: 34513 | J17: =YEARFRAC(I17,TODAY(),1) -> 32.192317 | K17: =YEARFRAC(I17,RG_DRH_S1_008!$E$4,1) -> 31.509925 | L17: =YEARFRAC(I17,RG_DRH_S1_008!$E$5,1) -> 32.509915 | M17: Conducteur de ligne | N17: E1450, E1400 | O17: Casa-Kenitra, Casa-Tanger , Casa-Marrakech, Fès - Casa | P17: 45537 | Q17: Apte classe 1 | R17: =YEARFRAC(I17,P17,1) -> 30.181401 | S17: =IF(L17<40,"4",IF(L17<50,"3",IF(L17<55,IF(Tableau3[[#This Row],[Fonction]]="Conducteur de ligne","2","3"),"1"))) -> 4 | T17: =EDATE(P17, (12*S17)) -> 46998 | U17: 44873 | V17: FAVORABLE MAINT | W17: =YEARFRAC(I17,U17,1) -> 28.364804 | X17: =IF(L17<40,"4",IF(L17<55,"3",IF(Tableau3[[#This Row],[Fonction]]="conducteur de ligne","1","2"))) -> 4 | Y17: =EDATE(U17, (12*X17)) -> 46334 | Z17: 45788 | AA17: =IF(Tableau3[[#This Row],[Date prochaine évaluation]]> TODAY(),"Réussi","Examen expiré") -> Examen expiré | AB17: =EDATE(Z17, 12) -> 46153 | AC17: =EDATE(AA17, 12) -> #VALUE!
B18: CHAOUI OUSSAMA | C18: 45024A | D18: Kénitra | F18: =IF(Tableau3[[#This Row],[Date d''expiration ]]>TODAY()+31,"✅",IF(Tableau3[[#This Row],[Date d''expiration ]]> TODAY()+1, "⚠️","⛔️")) -> ✅ | G18: =MIN(T18,Y18,AB18) -> 46430 | H18: =IF( Tableau3[[#This Row],[Date d''expiration ]]>TODAY(),"Néant","Cas à justifier") -> Néant | I18: 35797 | J18: =YEARFRAC(I18,TODAY(),1) -> 28.676926 | K18: =YEARFRAC(I18,RG_DRH_S1_008!$E$4,1) -> 27.994524 | L18: =YEARFRAC(I18,RG_DRH_S1_008!$E$5,1) -> 28.994524 | M18: Conducteur de ligne | N18: E1450, E1400, Z2M | O18: Casa-Kenitra, Casa-Tanger , Casa-Marrakech, Fès - Casa | P18: 45649 | Q18: Apte classe 1 | R18: =YEARFRAC(I18,P18,1) -> 26.972622 | S18: =IF(L18<40,"4",IF(L18<50,"3",IF(L18<55,IF(Tableau3[[#This Row],[Fonction]]="Conducteur de ligne","2","3"),"1"))) -> 4 | T18: =EDATE(P18, (12*S18)) -> 47110 | U18: 45897 | V18: FAVORABLE MAINT | W18: =YEARFRAC(I18,U18,1) -> 27.652293 | X18: =IF(L18<40,"4",IF(L18<55,"3",IF(Tableau3[[#This Row],[Fonction]]="conducteur de ligne","1","2"))) -> 4 | Y18: =EDATE(U18, (12*X18)) -> 47358 | Z18: 46065 | AA18: =IF(Tableau3[[#This Row],[Date prochaine évaluation]]> TODAY(),"Réussi","Examen expiré") -> Réussi | AB18: =EDATE(Z18, 12) -> 46430 | AC18: =EDATE(AA18, 12) -> #VALUE!
B19: CHOULI SOUFIANE | C19: 44007N | D19: Kénitra | F19: =IF(Tableau3[[#This Row],[Date d''expiration ]]>TODAY()+31,"✅",IF(Tableau3[[#This Row],[Date d''expiration ]]> TODAY()+1, "⚠️","⛔️")) -> ⛔️ | G19: =MIN(T19,Y19,AB19) -> 46159 | H19: =IF( Tableau3[[#This Row],[Date d''expiration ]]>TODAY(),"Néant","Cas à justifier") -> Cas à justifier | I19: 34027 | J19: =YEARFRAC(I19,TODAY(),1) -> 33.523595 | K19: =YEARFRAC(I19,RG_DRH_S1_008!$E$4,1) -> 32.841201 | L19: =YEARFRAC(I19,RG_DRH_S1_008!$E$5,1) -> 33.841198 | M19: Conducteur de ligne | N19: E1450, E1400, Z2M | O19: Casa-Kenitra, Casa-Tanger , Casa-Marrakech, Fès - Casa | P19: 45568 | Q19: Apte classe 1 | R19: =YEARFRAC(I19,P19,1) -> 31.597536 | S19: =IF(L19<40,"4",IF(L19<50,"3",IF(L19<55,IF(Tableau3[[#This Row],[Fonction]]="Conducteur de ligne","2","3"),"1"))) -> 4 | T19: =EDATE(P19, (12*S19)) -> 47029 | U19: 45166 | V19: FAVORABLE MAINT | W19: =YEARFRAC(I19,U19,1) -> 30.49894 | X19: =IF(L19<40,"4",IF(L19<55,"3",IF(Tableau3[[#This Row],[Fonction]]="conducteur de ligne","1","2"))) -> 4 | Y19: =EDATE(U19, (12*X19)) -> 46627 | Z19: 45794 | AA19: =IF(Tableau3[[#This Row],[Date prochaine évaluation]]> TODAY(),"Réussi","Examen expiré") -> Examen expiré | AB19: =EDATE(Z19, 12) -> 46159 | AC19: =EDATE(AA19, 12) -> #VALUE!
B20: CHTIOUI AZIZ | C20: 43722A | D20: Kénitra | F20: =IF(Tableau3[[#This Row],[Date d''expiration ]]>TODAY()+31,"✅",IF(Tableau3[[#This Row],[Date d''expiration ]]> TODAY()+1, "⚠️","⛔️")) -> ⚠️ | G20: =MIN(T20,Y20,AB20) -> 46299 | H20: =IF( Tableau3[[#This Row],[Date d''expiration ]]>TODAY(),"Néant","Cas à justifier") -> Néant | I20: 31922 | J20: =YEARFRAC(I20,TODAY(),1) -> 39.285421 | K20: =YEARFRAC(I20,RG_DRH_S1_008!$E$4,1) -> 38.603019 | L20: =YEARFRAC(I20,RG_DRH_S1_008!$E$5,1) -> 39.603012 | M20: Conducteur de ligne | N20: Z2M | O20: Casa-Kenitra | P20: 45454 | Q20: Apte classe 1 | R20: =YEARFRAC(I20,P20,1) -> 37.047262 | S20: =IF(L20<40,"4",IF(L20<50,"3",IF(L20<55,IF(Tableau3[[#This Row],[Fonction]]="Conducteur de ligne","2","3"),"1"))) -> 4 | T20: =EDATE(P20, (12*S20)) -> 46915 | U20: 45594 | V20: FAVORABLE MAINT | W20: =YEARFRAC(I20,U20,1) -> 37.430548 | X20: =IF(L20<40,"4",IF(L20<55,"3",IF(Tableau3[[#This Row],[Fonction]]="conducteur de ligne","1","2"))) -> 4 | Y20: =EDATE(U20, (12*X20)) -> 47055 | Z20: 45934 | AA20: =IF(Tableau3[[#This Row],[Date prochaine évaluation]]> TODAY(),"Réussi","Examen expiré") -> Réussi | AB20: =EDATE(Z20, 12) -> 46299 | AC20: =EDATE(AA20, 12) -> #VALUE!
B21: DAHANI MOHAMMED | C21: 43018L | D21: Kénitra | F21: =IF(Tableau3[[#This Row],[Date d''expiration ]]>TODAY()+31,"✅",IF(Tableau3[[#This Row],[Date d''expiration ]]> TODAY()+1, "⚠️","⛔️")) -> ⚠️ | G21: =MIN(T21,Y21,AB21) -> 46276 | H21: =IF( Tableau3[[#This Row],[Date d''expiration ]]>TODAY(),"Néant","Cas à justifier") -> Néant | I21: 32509 | J21: =YEARFRAC(I21,TODAY(),1) -> 37.67966 | K21: =YEARFRAC(I21,RG_DRH_S1_008!$E$4,1) -> 36.997262 | L21: =YEARFRAC(I21,RG_DRH_S1_008!$E$5,1) -> 37.997262 | M21: Conducteur de ligne | N21: E1450, E1400, Z2M, E1300, E1250 | O21: Casa-Kenitra, Casa-Tanger , Casa-Marrakech, Fès - Casa | P21: 45380 | Q21: Apte classe 1 | R21: =YEARFRAC(I21,P21,1) -> 35.238877 | S21: =IF(L21<40,"4",IF(L21<50,"3",IF(L21<55,IF(Tableau3[[#This Row],[Fonction]]="Conducteur de ligne","2","3"),"1"))) -> 4 | T21: =EDATE(P21, (12*S21)) -> 46841 | U21: 45722 | V21: FAVORABLE MAINT | W21: =YEARFRAC(I21,U21,1) -> 36.175892 | X21: =IF(L21<40,"4",IF(L21<55,"3",IF(Tableau3[[#This Row],[Fonction]]="conducteur de ligne","1","2"))) -> 4 | Y21: =EDATE(U21, (12*X21)) -> 47183 | Z21: 45911 | AA21: =IF(Tableau3[[#This Row],[Date prochaine évaluation]]> TODAY(),"Réussi","Examen expiré") -> Réussi | AB21: =EDATE(Z21, 12) -> 46276 | AC21: =EDATE(AA21, 12) -> #VALUE!
B22: DAHBI SALAH EDDINE | C22: 43701A | D22: Kénitra | F22: =IF(Tableau3[[#This Row],[Date d''expiration ]]>TODAY()+31,"✅",IF(Tableau3[[#This Row],[Date d''expiration ]]> TODAY()+1, "⚠️","⛔️")) -> ✅ | G22: =MIN(T22,Y22,AB22) -> 46431 | H22: =IF( Tableau3[[#This Row],[Date d''expiration ]]>TODAY(),"Néant","Cas à justifier") -> Néant | I22: 32791 | J22: =YEARFRAC(I22,TODAY(),1) -> 36.907558 | K22: =YEARFRAC(I22,RG_DRH_S1_008!$E$4,1) -> 36.225174 | L22: =YEARFRAC(I22,RG_DRH_S1_008!$E$5,1) -> 37.22516 | M22: Conducteur de ligne | N22: Z2M | O22: Casa-Kenitra | P22: 45412 | Q22: Apte classe 1 | R22: =YEARFRAC(I22,P22,1) -> 34.554415 | S22: =IF(L22<40,"4",IF(L22<50,"3",IF(L22<55,IF(Tableau3[[#This Row],[Fonction]]="Conducteur de ligne","2","3"),"1"))) -> 4 | T22: =EDATE(P22, (12*S22)) -> 46873 | U22: 45595 | V22: FAVORABLE MAINT | W22: =YEARFRAC(I22,U22,1) -> 35.055441 | X22: =IF(L22<40,"4",IF(L22<55,"3",IF(Tableau3[[#This Row],[Fonction]]="conducteur de ligne","1","2"))) -> 4 | Y22: =EDATE(U22, (12*X22)) -> 47056 | Z22: 46066 | AA22: =IF(Tableau3[[#This Row],[Date prochaine évaluation]]> TODAY(),"Réussi","Examen expiré") -> Réussi | AB22: =EDATE(Z22, 12) -> 46431 | AC22: =EDATE(AA22, 12) -> #VALUE!
B23: DIDI YOUNES | C23: 43406Z | D23: Kénitra | E23: 43297 | F23: =IF(Tableau3[[#This Row],[Date d''expiration ]]>TODAY()+31,"✅",IF(Tableau3[[#This Row],[Date d''expiration ]]> TODAY()+1, "⚠️","⛔️")) -> ✅ | G23: =MIN(T23,Y23,AB23) -> 46340 | H23: =IF( Tableau3[[#This Row],[Date d''expiration ]]>TODAY(),"Néant","Cas à justifier") -> Néant | I23: 33195 | J23: =YEARFRAC(I23,TODAY(),1) -> 35.800799 | K23: =YEARFRAC(I23,RG_DRH_S1_008!$E$4,1) -> 35.118412 | L23: =YEARFRAC(I23,RG_DRH_S1_008!$E$5,1) -> 36.118396 | M23: Conducteur de ligne | N23: E1450, E1400, E1300, E1250 | O23: Casa-Kenitra, Casa-Tanger , Casa-Marrakech, Fès - Casa | P23: 45007 | Q23: Apte classe 1 | R23: =YEARFRAC(I23,P23,1) -> 32.340796 | S23: =IF(L23<40,"4",IF(L23<50,"3",IF(L23<55,IF(Tableau3[[#This Row],[Fonction]]="Conducteur de ligne","2","3"),"1"))) -> 4 | T23: =EDATE(P23, (12*S23)) -> 46468 | U23: 45328 | V23: FAVORABLE MAINT | W23: =YEARFRAC(I23,U23,1) -> 33.217694 | X23: =IF(L23<40,"4",IF(L23<55,"3",IF(Tableau3[[#This Row],[Fonction]]="conducteur de ligne","1","2"))) -> 4 | Y23: =EDATE(U23, (12*X23)) -> 46789 | Z23: 45975 | AA23: =IF(Tableau3[[#This Row],[Date prochaine évaluation]]> TODAY(),"Réussi","Examen expiré") -> Réussi | AB23: =EDATE(Z23, 12) -> 46340 | AC23: =EDATE(AA23, 12) -> #VALUE!
B24: ECHOUIREF MOHAMMED | C24: 42691Y | D24: Kénitra | F24: =IF(Tableau3[[#This Row],[Date d''expiration ]]>TODAY()+31,"✅",IF(Tableau3[[#This Row],[Date d''expiration ]]> TODAY()+1, "⚠️","⛔️")) -> ✅ | G24: =MIN(T24,Y24,AB24) -> 46551 | H24: =IF( Tableau3[[#This Row],[Date d''expiration ]]>TODAY(),"Néant","Cas à justifier") -> Néant | I24: 31626 | J24: =YEARFRAC(I24,TODAY(),1) -> 40.096494 | K24: =YEARFRAC(I24,RG_DRH_S1_008!$E$4,1) -> 39.4141 | L24: =YEARFRAC(I24,RG_DRH_S1_008!$E$5,1) -> 40.41409 | M24: Conducteur de ligne | N24: E1450, E1400, E1300, E1250 | O24: Casa-Kenitra, Casa-Tanger , Casa-Marrakech, Fès - Casa | P24: 46191 | Q24: Apte classe 1 | R24: =YEARFRAC(I24,P24,1) -> 39.877462 | S24: =IF(L24<40,"4",IF(L24<50,"3",IF(L24<55,IF(Tableau3[[#This Row],[Fonction]]="Conducteur de ligne","2","3"),"1"))) -> 3 | T24: =EDATE(P24, (12*S24)) -> 47287 | U24: 46191 | V24: FAVORABLE MAINT | W24: =YEARFRAC(I24,U24,1) -> 39.877462 | X24: =IF(L24<40,"4",IF(L24<55,"3",IF(Tableau3[[#This Row],[Fonction]]="conducteur de ligne","1","2"))) -> 3 | Y24: =EDATE(U24, (12*X24)) -> 47287 | Z24: 46186 | AA24: =IF(Tableau3[[#This Row],[Date prochaine évaluation]]> TODAY(),"Réussi","Examen expiré") -> Réussi | AB24: =EDATE(Z24, 12) -> 46551 | AC24: =EDATE(AA24, 12) -> #VALUE!
B25: EL BOUNI ANAS | C25: 42413R | D25: Kénitra | F25: =IF(Tableau3[[#This Row],[Date d''expiration ]]>TODAY()+31,"✅",IF(Tableau3[[#This Row],[Date d''expiration ]]> TODAY()+1, "⚠️","⛔️")) -> ✅ | G25: =MIN(T25,Y25,AB25) -> 46311 | H25: =IF( Tableau3[[#This Row],[Date d''expiration ]]>TODAY(),"Néant","Cas à justifier") -> Néant | I25: 32784 | J25: =YEARFRAC(I25,TODAY(),1) -> 36.926724 | K25: =YEARFRAC(I25,RG_DRH_S1_008!$E$4,1) -> 36.244339 | L25: =YEARFRAC(I25,RG_DRH_S1_008!$E$5,1) -> 37.244326 | M25: Conducteur de ligne | N25: Z2M | O25: Casa-Kenitra | P25: 45754 | Q25: Apte classe 1 | R25: =YEARFRAC(I25,P25,1) -> 35.510582 | S25: =IF(L25<40,"4",IF(L25<50,"3",IF(L25<55,IF(Tableau3[[#This Row],[Fonction]]="Conducteur de ligne","2","3"),"1"))) -> 4 | T25: =EDATE(P25, (12*S25)) -> 47215 | U25: 44985 | V25: FAVORABLE MAINT | W25: =YEARFRAC(I25,U25,1) -> 33.406477 | X25: =IF(L25<40,"4",IF(L25<55,"3",IF(Tableau3[[#This Row],[Fonction]]="conducteur de ligne","1","2"))) -> 4 | Y25: =EDATE(U25, (12*X25)) -> 46446 | Z25: 45946 | AA25: =IF(Tableau3[[#This Row],[Date prochaine évaluation]]> TODAY(),"Réussi","Examen expiré") -> Réussi | AB25: =EDATE(Z25, 12) -> 46311 | AC25: =EDATE(AA25, 12) -> #VALUE!
B26: EL FAID KHALID | C26: 45280E | D26: Kénitra | F26: =IF(Tableau3[[#This Row],[Date d''expiration ]]>TODAY()+31,"✅",IF(Tableau3[[#This Row],[Date d''expiration ]]> TODAY()+1, "⚠️","⛔️")) -> ✅ | G26: =MIN(T26,Y26,AB26) -> 46313 | H26: =IF( Tableau3[[#This Row],[Date d''expiration ]]>TODAY(),"Néant","Cas à justifier") -> Néant | I26: 34990 | J26: =YEARFRAC(I26,TODAY(),1) -> 30.885695 | K26: =YEARFRAC(I26,RG_DRH_S1_008!$E$4,1) -> 30.203303 | L26: =YEARFRAC(I26,RG_DRH_S1_008!$E$5,1) -> 31.203285 | M26: Conducteur de ligne | N26: E1400, E1450 | O26: Casa-Kenitra, Casa-Tanger , Casa-Marrakech, Fès - Casa | P26: 45567 | Q26: Apte classe 1 | R26: =YEARFRAC(I26,P26,1) -> 28.956926 | S26: =IF(L26<40,"4",IF(L26<50,"3",IF(L26<55,IF(Tableau3[[#This Row],[Fonction]]="Conducteur de ligne","2","3"),"1"))) -> 4 | T26: =EDATE(P26, (12*S26)) -> 47028 | U26: 44852 | V26: FAVORABLE MAINT | W26: =YEARFRAC(I26,U26,1) -> 27.000684 | X26: =IF(L26<40,"4",IF(L26<55,"3",IF(Tableau3[[#This Row],[Fonction]]="conducteur de ligne","1","2"))) -> 4 | Y26: =EDATE(U26, (12*X26)) -> 46313 | Z26: 46133 | AA26: =IF(Tableau3[[#This Row],[Date prochaine évaluation]]> TODAY(),"Réussi","Examen expiré") -> Réussi | AB26: =EDATE(Z26, 12) -> 46498 | AC26: =EDATE(AA26, 12) -> #VALUE!
B27: EL FILALI LAMDAGHRI SOUFIANE | C27: 43993Y | D27: Kénitra | F27: =IF(Tableau3[[#This Row],[Date d''expiration ]]>TODAY()+31,"✅",IF(Tableau3[[#This Row],[Date d''expiration ]]> TODAY()+1, "⚠️","⛔️")) -> ✅ | G27: =MIN(T27,Y27,AB27) -> 46473 | H27: =IF( Tableau3[[#This Row],[Date d''expiration ]]>TODAY(),"Néant","Cas à justifier") -> Néant | I27: 33765 | J27: =YEARFRAC(I27,TODAY(),1) -> 34.238892 | K27: =YEARFRAC(I27,RG_DRH_S1_008!$E$4,1) -> 33.556486 | L27: =YEARFRAC(I27,RG_DRH_S1_008!$E$5,1) -> 34.556477 | M27: Conducteur de ligne | N27: E1450, E1400, E1250, E1300 | O27: Casa-Kenitra, Casa-Tanger , Casa-Marrakech, Fès - Casa | P27: 45674 | Q27: Apte classe 1 | R27: =YEARFRAC(I27,P27,1) -> 32.603752 | S27: =IF(L27<40,"4",IF(L27<50,"3",IF(L27<55,IF(Tableau3[[#This Row],[Fonction]]="Conducteur de ligne","2","3"),"1"))) -> 4 | T27: =EDATE(P27, (12*S27)) -> 47135 | U27: 45140 | V27: FAVORABLE MAINT | W27: =YEARFRAC(I27,U27,1) -> 31.143053 | X27: =IF(L27<40,"4",IF(L27<55,"3",IF(Tableau3[[#This Row],[Fonction]]="conducteur de ligne","1","2"))) -> 4 | Y27: =EDATE(U27, (12*X27)) -> 46601 | Z27: 46108 | AA27: =IF(Tableau3[[#This Row],[Date prochaine évaluation]]> TODAY(),"Réussi","Examen expiré") -> Réussi | AB27: =EDATE(Z27, 12) -> 46473 | AC27: =EDATE(AA27, 12) -> #VALUE!
B28: EL HAJJI HICHAM | C28: 43163J | D28: Kénitra | F28: =IF(Tableau3[[#This Row],[Date d''expiration ]]>TODAY()+31,"✅",IF(Tableau3[[#This Row],[Date d''expiration ]]> TODAY()+1, "⚠️","⛔️")) -> ✅ | G28: =MIN(T28,Y28,AB28) -> 46428 | H28: =IF( Tableau3[[#This Row],[Date d''expiration ]]>TODAY(),"Néant","Cas à justifier") -> Néant | I28: 31611 | J28: =YEARFRAC(I28,TODAY(),1) -> 40.137563 | K28: =YEARFRAC(I28,RG_DRH_S1_008!$E$4,1) -> 39.455168 | L28: =YEARFRAC(I28,RG_DRH_S1_008!$E$5,1) -> 40.455159 | M28: Conducteur de ligne | N28: E1450, E1400 | O28: Casa-Kenitra, Casa-Tanger , Casa-Marrakech, Fès - Casa | P28: 45971 | Q28: Apte classe 1 | R28: =YEARFRAC(I28,P28,1) -> 39.315537 | S28: =IF(L28<40,"4",IF(L28<50,"3",IF(L28<55,IF(Tableau3[[#This Row],[Fonction]]="Conducteur de ligne","2","3"),"1"))) -> 3 | T28: =EDATE(P28, (12*S28)) -> 47067 | U28: 45373 | V28: FAVORABLE MAINT | W28: =YEARFRAC(I28,U28,1) -> 37.677641 | X28: =IF(L28<40,"4",IF(L28<55,"3",IF(Tableau3[[#This Row],[Fonction]]="conducteur de ligne","1","2"))) -> 3 | Y28: =EDATE(U28, (12*X28)) -> 46468 | Z28: 46063 | AA28: =IF(Tableau3[[#This Row],[Date prochaine évaluation]]> TODAY(),"Réussi","Examen expiré") -> Réussi | AB28: =EDATE(Z28, 12) -> 46428 | AC28: =EDATE(AA28, 12) -> #VALUE!
B29: EL MILAOUI AYOUB | C29: 43999E | D29: Kénitra | F29: =IF(Tableau3[[#This Row],[Date d''expiration ]]>TODAY()+31,"✅",IF(Tableau3[[#This Row],[Date d''expiration ]]> TODAY()+1, "⚠️","⛔️")) -> ✅ | G29: =MIN(T29,Y29,AB29) -> 46331 | H29: =IF( Tableau3[[#This Row],[Date d''expiration ]]>TODAY(),"Néant","Cas à justifier") -> Néant | I29: 33720 | J29: =YEARFRAC(I29,TODAY(),1) -> 34.362093 | K29: =YEARFRAC(I29,RG_DRH_S1_008!$E$4,1) -> 33.679684 | L29: =YEARFRAC(I29,RG_DRH_S1_008!$E$5,1) -> 34.679678 | M29: Conducteur de ligne | N29: E1400, E1450 | O29: Fès - Casa, Casa-Kenitra, Casa-Tanger , Casa-Marrakech, Casa-Eljadida | P29: 45398 | Q29: Apte classe 1 | R29: =YEARFRAC(I29,P29,1) -> 31.970632 | S29: =IF(L29<40,"4",IF(L29<50,"3",IF(L29<55,IF(Tableau3[[#This Row],[Fonction]]="Conducteur de ligne","2","3"),"1"))) -> 4 | T29: =EDATE(P29, (12*S29)) -> 46859 | U29: 45398 | V29: FAVORABLE MAINT | W29: =YEARFRAC(I29,U29,1) -> 31.970632 | X29: =IF(L29<40,"4",IF(L29<55,"3",IF(Tableau3[[#This Row],[Fonction]]="conducteur de ligne","1","2"))) -> 4 | Y29: =EDATE(U29, (12*X29)) -> 46859 | Z29: 45966 | AA29: =IF(Tableau3[[#This Row],[Date prochaine évaluation]]> TODAY(),"Réussi","Examen expiré") -> Réussi | AB29: =EDATE(Z29, 12) -> 46331 | AC29: =EDATE(AA29, 12) -> #VALUE!
B30: ELHIMER TAREK | C30: 45026C | D30: Kénitra | F30: =IF(Tableau3[[#This Row],[Date d''expiration ]]>TODAY()+31,"✅",IF(Tableau3[[#This Row],[Date d''expiration ]]> TODAY()+1, "⚠️","⛔️")) -> ✅ | G30: =MIN(T30,Y30,AB30) -> 46431 | H30: =IF( Tableau3[[#This Row],[Date d''expiration ]]>TODAY(),"Néant","Cas à justifier") -> Néant | I30: 34723 | J30: =YEARFRAC(I30,TODAY(),1) -> 31.616701 | K30: =YEARFRAC(I30,RG_DRH_S1_008!$E$4,1) -> 30.934293 | L30: =YEARFRAC(I30,RG_DRH_S1_008!$E$5,1) -> 31.934292 | M30: Conducteur de ligne | N30: E1450, E1400, Z2M | O30: Casa-Kenitra, Casa-Tanger , Casa-Marrakech, Fès - Casa | P30: 45327 | Q30: Apte classe 1 | R30: =YEARFRAC(I30,P30,1) -> 29.030845 | S30: =IF(L30<40,"4",IF(L30<50,"3",IF(L30<55,IF(Tableau3[[#This Row],[Fonction]]="Conducteur de ligne","2","3"),"1"))) -> 4 | T30: =EDATE(P30, (12*S30)) -> 46788 | U30: 45572 | V30: FAVORABLE MAINT | W30: =YEARFRAC(I30,U30,1) -> 29.701588 | X30: =IF(L30<40,"4",IF(L30<55,"3",IF(Tableau3[[#This Row],[Fonction]]="conducteur de ligne","1","2"))) -> 4 | Y30: =EDATE(U30, (12*X30)) -> 47033 | Z30: 46066 | AA30: =IF(Tableau3[[#This Row],[Date prochaine évaluation]]> TODAY(),"Réussi","Examen expiré") -> Réussi | AB30: =EDATE(Z30, 12) -> 46431 | AC30: =EDATE(AA30, 12) -> #VALUE!
B31: ENNSEIRI ILIASS | C31: 43902N | D31: Kénitra | F31: =IF(Tableau3[[#This Row],[Date d''expiration ]]>TODAY()+31,"✅",IF(Tableau3[[#This Row],[Date d''expiration ]]> TODAY()+1, "⚠️","⛔️")) -> ✅ | G31: =MIN(T31,Y31,AB31) -> 46540 | H31: =IF( Tableau3[[#This Row],[Date d''expiration ]]>TODAY(),"Néant","Cas à justifier") -> Néant | I31: 34744 | J31: =YEARFRAC(I31,TODAY(),1) -> 31.559206 | K31: =YEARFRAC(I31,RG_DRH_S1_008!$E$4,1) -> 30.876799 | L31: =YEARFRAC(I31,RG_DRH_S1_008!$E$5,1) -> 31.876797 | M31: Conducteur de ligne | N31: E1400, E1450 | O31: Casa-Kenitra, Casa-Tanger , Casa-Marrakech, Fès - Casa | P31: 45610 | Q31: Apte classe 1 | R31: =YEARFRAC(I31,P31,1) -> 29.748129 | S31: =IF(L31<40,"4",IF(L31<50,"3",IF(L31<55,IF(Tableau3[[#This Row],[Fonction]]="Conducteur de ligne","2","3"),"1"))) -> 4 | T31: =EDATE(P31, (12*S31)) -> 47071 | U31: 45148 | V31: FAVORABLE MAINT | W31: =YEARFRAC(I31,U31,1) -> 28.485272 | X31: =IF(L31<40,"4",IF(L31<55,"3",IF(Tableau3[[#This Row],[Fonction]]="conducteur de ligne","1","2"))) -> 4 | Y31: =EDATE(U31, (12*X31)) -> 46609 | Z31: 46175 | AA31: =IF(Tableau3[[#This Row],[Date prochaine évaluation]]> TODAY(),"Réussi","Examen expiré") -> Réussi | AB31: =EDATE(Z31, 12) -> 46540 | AC31: =EDATE(AA31, 12) -> #VALUE!
B32: ESSAADAOUI ABDELJALIL | C32: 44783M | D32: Kénitra | F32: =IF(Tableau3[[#This Row],[Date d''expiration ]]>TODAY()+31,"✅",IF(Tableau3[[#This Row],[Date d''expiration ]]> TODAY()+1, "⚠️","⛔️")) -> ✅ | G32: =MIN(T32,Y32,AB32) -> 46429 | H32: =IF( Tableau3[[#This Row],[Date d''expiration ]]>TODAY(),"Néant","Cas à justifier") -> Néant | I32: 34257 | J32: =YEARFRAC(I32,TODAY(),1) -> 32.893864 | K32: =YEARFRAC(I32,RG_DRH_S1_008!$E$4,1) -> 32.211483 | L32: =YEARFRAC(I32,RG_DRH_S1_008!$E$5,1) -> 33.211467 | M32: Conducteur de ligne | N32: E1450, E1400 | O32: Casa-Kenitra, Casa-Tanger , Casa-Marrakech, Fès - Casa | P32: 45013 | Q32: Apte classe 1 | R32: =YEARFRAC(I32,P32,1) -> 29.450274 | S32: =IF(L32<40,"4",IF(L32<50,"3",IF(L32<55,IF(Tableau3[[#This Row],[Fonction]]="Conducteur de ligne","2","3"),"1"))) -> 4 | T32: =EDATE(P32, (12*S32)) -> 46474 | U32: 45975 | V32: FAVORABLE MAINT | W32: =YEARFRAC(I32,U32,1) -> 32.082801 | X32: =IF(L32<40,"4",IF(L32<55,"3",IF(Tableau3[[#This Row],[Fonction]]="conducteur de ligne","1","2"))) -> 4 | Y32: =EDATE(U32, (12*X32)) -> 47436 | Z32: 46064 | AA32: =IF(Tableau3[[#This Row],[Date prochaine évaluation]]> TODAY(),"Réussi","Examen expiré") -> Réussi | AB32: =EDATE(Z32, 12) -> 46429 | AC32: =EDATE(AA32, 12) -> #VALUE!
B33: FERKOUKI OMAR | C33: 45031H | D33: Kénitra | F33: =IF(Tableau3[[#This Row],[Date d''expiration ]]>TODAY()+31,"✅",IF(Tableau3[[#This Row],[Date d''expiration ]]> TODAY()+1, "⚠️","⛔️")) -> ✅ | G33: =MIN(T33,Y33,AB33) -> 46432 | H33: =IF( Tableau3[[#This Row],[Date d''expiration ]]>TODAY(),"Néant","Cas à justifier") -> Néant | I33: 34391 | J33: =YEARFRAC(I33,TODAY(),1) -> 32.526342 | K33: =YEARFRAC(I33,RG_DRH_S1_008!$E$4,1) -> 31.843943 | L33: =YEARFRAC(I33,RG_DRH_S1_008!$E$5,1) -> 32.843939 | M33: Conducteur de ligne | N33: E1450, E1400, Z2M | O33: Casa-Kenitra, Casa-Tanger , Casa-Marrakech, Fès - Casa | P33: 45203 | Q33: Apte classe 1 | R33: =YEARFRAC(I33,P33,1) -> 29.602994 | S33: =IF(L33<40,"4",IF(L33<50,"3",IF(L33<55,IF(Tableau3[[#This Row],[Fonction]]="Conducteur de ligne","2","3"),"1"))) -> 4 | T33: =EDATE(P33, (12*S33)) -> 46664 | U33: 45575 | V33: FAVORABLE MAINT | W33: =YEARFRAC(I33,U33,1) -> 30.619447 | X33: =IF(L33<40,"4",IF(L33<55,"3",IF(Tableau3[[#This Row],[Fonction]]="conducteur de ligne","1","2"))) -> 4 | Y33: =EDATE(U33, (12*X33)) -> 47036 | Z33: 46067 | AA33: =IF(Tableau3[[#This Row],[Date prochaine évaluation]]> TODAY(),"Réussi","Examen expiré") -> Réussi | AB33: =EDATE(Z33, 12) -> 46432 | AC33: =EDATE(AA33, 12) -> #VALUE!
B34: ZEGMOU MUSTAPHA | C34: 40589W | D34: Kénitra | F34: =IF(Tableau3[[#This Row],[Date d''expiration ]]>TODAY()+31,"✅",IF(Tableau3[[#This Row],[Date d''expiration ]]> TODAY()+1, "⚠️","⛔️")) -> ⛔️ | G34: =MIN(T34,Y34,AB34) -> 45895 | H34: RETRAITE | I34: 25062 | J34: =YEARFRAC(I34,TODAY(),1) -> 58.066404 | K34: =YEARFRAC(I34,RG_DRH_S1_008!$E$4,1) -> 57.383998 | L34: =YEARFRAC(I34,RG_DRH_S1_008!$E$5,1) -> 58.383991 | M34: Conducteur de ligne | N34: Z2M | O34: Casa-Kenitra | P34: 45532 | Q34: Apte classe 1 | R34: =YEARFRAC(I34,P34,1) -> 56.041787 | S34: =IF(L34<40,"4",IF(L34<50,"3",IF(L34<55,IF(Tableau3[[#This Row],[Fonction]]="Conducteur de ligne","2","3"),"1"))) -> 1 | T34: =EDATE(P34, (12*S34)) -> 45897 | U34: 45530 | V34: FAVORABLE MAINT | W34: =YEARFRAC(I34,U34,1) -> 56.036311 | X34: =IF(L34<40,"4",IF(L34<55,"3",IF(Tableau3[[#This Row],[Fonction]]="conducteur de ligne","1","2"))) -> 1 | Y34: =EDATE(U34, (12*X34)) -> 45895 | Z34: 45818 | AA34: =IF(Tableau3[[#This Row],[Date prochaine évaluation]]> TODAY(),"Réussi","Examen expiré") -> Examen expiré | AB34: =EDATE(Z34, 12) -> 46183 | AC34: =EDATE(AA34, 12) -> #VALUE!
B35: ZARHOUNI DRISS | C35: 85642E | D35: Kénitra | F35: =IF(Tableau3[[#This Row],[Date d''expiration ]]>TODAY()+31,"✅",IF(Tableau3[[#This Row],[Date d''expiration ]]> TODAY()+1, "⚠️","⛔️")) -> ✅ | G35: =MIN(T35,Y35,AB35) -> 46580 | H35: =IF( Tableau3[[#This Row],[Date d''expiration ]]>TODAY(),"Néant","Cas à justifier") -> Néant | I35: 28567 | J35: =YEARFRAC(I35,TODAY(),1) -> 48.471587 | K35: =YEARFRAC(I35,RG_DRH_S1_008!$E$4,1) -> 47.789185 | L35: =YEARFRAC(I35,RG_DRH_S1_008!$E$5,1) -> 48.789183 | M35: Conducteur de ligne | N35: E1450, E1400, Z2M | O35: Casa-Kenitra, Casa-Tanger , Casa-Marrakech, Fès - Casa | P35: 45485 | Q35: Apte classe 1 | R35: =YEARFRAC(I35,P35,1) -> 46.318285 | S35: =IF(L35<40,"4",IF(L35<50,"3",IF(L35<55,IF(Tableau3[[#This Row],[Fonction]]="Conducteur de ligne","2","3"),"1"))) -> 3 | T35: =EDATE(P35, (12*S35)) -> 46580 | U35: 45768 | V35: FAVORABLE MAINT | W35: =YEARFRAC(I35,U35,1) -> 47.093771 | X35: =IF(L35<40,"4",IF(L35<55,"3",IF(Tableau3[[#This Row],[Fonction]]="conducteur de ligne","1","2"))) -> 3 | Y35: =EDATE(U35, (12*X35)) -> 46864 | Z35: 46216 | AA35: =IF(Tableau3[[#This Row],[Date prochaine évaluation]]> TODAY(),"Réussi","Examen expiré") -> Réussi | AB35: =EDATE(Z35, 12) -> 46581 | AC35: =EDATE(AA35, 12) -> #VALUE!
B36: RACHAD EL KHALIL | C36: 85436J | D36: Kénitra | F36: =IF(Tableau3[[#This Row],[Date d''expiration ]]>TODAY()+31,"✅",IF(Tableau3[[#This Row],[Date d''expiration ]]> TODAY()+1, "⚠️","⛔️")) -> ✅ | G36: =MIN(T36,Y36,AB36) -> 46436 | H36: =IF( Tableau3[[#This Row],[Date d''expiration ]]>TODAY(),"Néant","Cas à justifier") -> Néant | I36: 27573 | J36: =YEARFRAC(I36,TODAY(),1) -> 51.192334 | K36: =YEARFRAC(I36,RG_DRH_S1_008!$E$4,1) -> 50.509931 | L36: =YEARFRAC(I36,RG_DRH_S1_008!$E$5,1) -> 51.509925 | M36: Conducteur de ligne | N36: Z2M | O36: Casa-Kenitra | P36: 45833 | Q36: Apte classe 1 | R36: =YEARFRAC(I36,P36,1) -> 49.992484 | S36: =IF(L36<40,"4",IF(L36<50,"3",IF(L36<55,IF(Tableau3[[#This Row],[Fonction]]="Conducteur de ligne","2","3"),"1"))) -> 2 | T36: =EDATE(P36, (12*S36)) -> 46563 | U36: 45478 | V36: FAVORABLE MAINT | W36: =YEARFRAC(I36,U36,1) -> 49.019876 | X36: =IF(L36<40,"4",IF(L36<55,"3",IF(Tableau3[[#This Row],[Fonction]]="conducteur de ligne","1","2"))) -> 3 | Y36: =EDATE(U36, (12*X36)) -> 46573 | Z36: 46071 | AA36: =IF(Tableau3[[#This Row],[Date prochaine évaluation]]> TODAY(),"Réussi","Examen expiré") -> Réussi | AB36: =EDATE(Z36, 12) -> 46436 | AC36: =EDATE(AA36, 12) -> #VALUE!
B37: LAAROUBI YOUSSEF | C37: 40614A | D37: Kénitra | F37: =IF(Tableau3[[#This Row],[Date d''expiration ]]>TODAY()+31,"✅",IF(Tableau3[[#This Row],[Date d''expiration ]]> TODAY()+1, "⚠️","⛔️")) -> ✅ | G37: =MIN(T37,Y37,AB37) -> 46339 | H37: =IF( Tableau3[[#This Row],[Date d''expiration ]]>TODAY(),"Néant","Cas à justifier") -> Néant | I37: 25637 | J37: =YEARFRAC(I37,TODAY(),1) -> 56.493492 | K37: =YEARFRAC(I37,RG_DRH_S1_008!$E$4,1) -> 55.811088 | L37: =YEARFRAC(I37,RG_DRH_S1_008!$E$5,1) -> 56.811086 | M37: Conducteur de ligne | N37: E1450, E1400, E1300, E1250 | O37: Casa-Kenitra, Casa-Tanger , Casa-Marrakech, Fès - Casa | P37: 46105 | Q37: Apte classe 1 | R37: =YEARFRAC(I37,P37,1) -> 56.039003 | S37: =IF(L37<40,"4",IF(L37<50,"3",IF(L37<55,IF(Tableau3[[#This Row],[Fonction]]="Conducteur de ligne","2","3"),"1"))) -> 1 | T37: =EDATE(P37, (12*S37)) -> 46470 | U37: 46119 | V37: FAVORABLE MAINT | W37: =YEARFRAC(I37,U37,1) -> 56.077333 | X37: =IF(L37<40,"4",IF(L37<55,"3",IF(Tableau3[[#This Row],[Fonction]]="conducteur de ligne","1","2"))) -> 1 | Y37: =EDATE(U37, (12*X37)) -> 46484 | Z37: 45974 | AA37: =IF(Tableau3[[#This Row],[Date prochaine évaluation]]> TODAY(),"Réussi","Examen expiré") -> Réussi | AB37: =EDATE(Z37, 12) -> 46339 | AC37: =EDATE(AA37, 12) -> #VALUE!
B38: EL KHADIR ABDELKADER | C38: 85586M | D38: Kénitra | F38: =IF(Tableau3[[#This Row],[Date d''expiration ]]>TODAY()+31,"✅",IF(Tableau3[[#This Row],[Date d''expiration ]]> TODAY()+1, "⚠️","⛔️")) -> ⛔️ | G38: =MIN(T38,Y38,AB38) -> 46095 | H38: Néant | I38: 27211 | J38: =YEARFRAC(I38,TODAY(),1) -> 52.18411 | K38: =YEARFRAC(I38,RG_DRH_S1_008!$E$4,1) -> 51.501711 | L38: =YEARFRAC(I38,RG_DRH_S1_008!$E$5,1) -> 52.501705 | M38: Conducteur de ligne | N38: Z2M, E1300, E1250, E1400, E1450 | O38: Casa-Kenitra, Casa-Tanger , Casa-Marrakech, Fès - Casa | P38: 45765 | Q38: Apte classe 1 | R38: =YEARFRAC(I38,P38,1) -> 50.798084 | S38: =IF(L38<40,"4",IF(L38<50,"3",IF(L38<55,IF(Tableau3[[#This Row],[Fonction]]="Conducteur de ligne","2","3"),"1"))) -> 2 | T38: =EDATE(P38, (12*S38)) -> 46495 | U38: 44999 | V38: FAVORABLE MAINT | W38: =YEARFRAC(I38,U38,1) -> 48.702223 | X38: =IF(L38<40,"4",IF(L38<55,"3",IF(Tableau3[[#This Row],[Fonction]]="conducteur de ligne","1","2"))) -> 3 | Y38: =EDATE(U38, (12*X38)) -> 46095 | Z38: 45957 | AA38: =IF(Tableau3[[#This Row],[Date prochaine évaluation]]> TODAY(),"Réussi","Examen expiré") -> Réussi | AB38: =EDATE(Z38, 12) -> 46322 | AC38: =EDATE(AA38, 12) -> #VALUE!
B39: GATRA MOHAMED | C39: 45400Y | D39: Kénitra | F39: =IF(Tableau3[[#This Row],[Date d''expiration ]]>TODAY()+31,"✅",IF(Tableau3[[#This Row],[Date d''expiration ]]> TODAY()+1, "⚠️","⛔️")) -> ✅ | G39: =MIN(T39,Y39,AB39) -> 46494 | H39: =IF( Tableau3[[#This Row],[Date d''expiration ]]>TODAY(),"Néant","Cas à justifier") -> Néant | I39: 35113 | J39: =YEARFRAC(I39,TODAY(),1) -> 30.548265 | K39: =YEARFRAC(I39,RG_DRH_S1_008!$E$4,1) -> 29.865851 | L39: =YEARFRAC(I39,RG_DRH_S1_008!$E$5,1) -> 30.865848 | M39: Conducteur de ligne | N39: E1450, E1400 | O39: Casa-Kenitra, Casa-Tanger , Casa-Marrakech, Fès - Casa | P39: 45317 | Q39: Apte classe 1 | R39: =YEARFRAC(I39,P39,1) -> 27.935051 | S39: =IF(L39<40,"4",IF(L39<50,"3",IF(L39<55,IF(Tableau3[[#This Row],[Fonction]]="Conducteur de ligne","2","3"),"1"))) -> 4 | T39: =EDATE(P39, (12*S39)) -> 46778 | U39: 45033 | V39: FAVORABLE MAINT | W39: =YEARFRAC(I39,U39,1) -> 27.15948 | X39: =IF(L39<40,"4",IF(L39<55,"3",IF(Tableau3[[#This Row],[Fonction]]="conducteur de ligne","1","2"))) -> 4 | Y39: =EDATE(U39, (12*X39)) -> 46494 | Z39: 46139 | AA39: =IF(Tableau3[[#This Row],[Date prochaine évaluation]]> TODAY(),"Réussi","Examen expiré") -> Réussi | AB39: =EDATE(Z39, 12) -> 46504 | AC39: =EDATE(AA39, 12) -> #VALUE!
B40: CHRAIT MUSTAPHA | C40: 85517F | D40: Kénitra | F40: =IF(Tableau3[[#This Row],[Date d''expiration ]]>TODAY()+31,"✅",IF(Tableau3[[#This Row],[Date d''expiration ]]> TODAY()+1, "⚠️","⛔️")) -> ✅ | G40: =MIN(T40,Y40,AB40) -> 46317 | H40: =IF( Tableau3[[#This Row],[Date d''expiration ]]>TODAY(),"Néant","Cas à justifier") -> Néant | I40: 29768 | J40: =YEARFRAC(I40,TODAY(),1) -> 45.184096 | K40: =YEARFRAC(I40,RG_DRH_S1_008!$E$4,1) -> 44.501704 | L40: =YEARFRAC(I40,RG_DRH_S1_008!$E$5,1) -> 45.501696 | M40: Conducteur de ligne | N40: E1450, E1400, E1300, E1250 | O40: Casa-Kenitra, Casa-Tanger , Casa-Marrakech, Fès - Casa | P40: 45789 | Q40: Apte classe 1 | R40: =YEARFRAC(I40,P40,1) -> 43.863775 | S40: =IF(L40<40,"4",IF(L40<50,"3",IF(L40<55,IF(Tableau3[[#This Row],[Fonction]]="Conducteur de ligne","2","3"),"1"))) -> 3 | T40: =EDATE(P40, (12*S40)) -> 46885 | U40: 45786 | V40: FAVORABLE MAINT | W40: =YEARFRAC(I40,U40,1) -> 43.855561 | X40: =IF(L40<40,"4",IF(L40<55,"3",IF(Tableau3[[#This Row],[Fonction]]="conducteur de ligne","1","2"))) -> 3 | Y40: =EDATE(U40, (12*X40)) -> 46882 | Z40: 45952 | AA40: =IF(Tableau3[[#This Row],[Date prochaine évaluation]]> TODAY(),"Réussi","Examen expiré") -> Réussi | AB40: =EDATE(Z40, 12) -> 46317 | AC40: =EDATE(AA40, 12) -> #VALUE!
B41: IOUNOUSSE OMAR | C41: 44788T | D41: Kénitra | F41: =IF(Tableau3[[#This Row],[Date d''expiration ]]>TODAY()+31,"✅",IF(Tableau3[[#This Row],[Date d''expiration ]]> TODAY()+1, "⚠️","⛔️")) -> ✅ | G41: =MIN(T41,Y41,AB41) -> 46422 | H41: =IF( Tableau3[[#This Row],[Date d''expiration ]]>TODAY(),"Néant","Cas à justifier") -> Néant | I41: 34727 | J41: =YEARFRAC(I41,TODAY(),1) -> 31.605749 | K41: =YEARFRAC(I41,RG_DRH_S1_008!$E$4,1) -> 30.923342 | L41: =YEARFRAC(I41,RG_DRH_S1_008!$E$5,1) -> 31.92334 | M41: Conducteur de ligne | N41: E1450, E1400 | O41: Casa-Kenitra, Casa-Tanger , Casa-Marrakech, Fès - Casa | P41: 45964 | Q41: Apte classe 1 | R41: =YEARFRAC(I41,P41,1) -> 30.76455 | S41: =IF(L41<40,"4",IF(L41<50,"3",IF(L41<55,IF(Tableau3[[#This Row],[Fonction]]="Conducteur de ligne","2","3"),"1"))) -> 4 | T41: =EDATE(P41, (12*S41)) -> 47425 | U41: 45971 | V41: FAVORABLE MAINT | W41: =YEARFRAC(I41,U41,1) -> 30.783715 | X41: =IF(L41<40,"4",IF(L41<55,"3",IF(Tableau3[[#This Row],[Fonction]]="conducteur de ligne","1","2"))) -> 4 | Y41: =EDATE(U41, (12*X41)) -> 47432 | Z41: 46057 | AA41: =IF(Tableau3[[#This Row],[Date prochaine évaluation]]> TODAY(),"Réussi","Examen expiré") -> Réussi | AB41: =EDATE(Z41, 12) -> 46422 | AC41: =EDATE(AA41, 12) -> #VALUE!
B42: CHAHED MOHAMED LARBI | C42: 85563K | D42: Kénitra | F42: =IF(Tableau3[[#This Row],[Date d''expiration ]]>TODAY()+31,"✅",IF(Tableau3[[#This Row],[Date d''expiration ]]> TODAY()+1, "⚠️","⛔️")) -> ✅ | G42: =MIN(T42,Y42,AB42) -> 46541 | H42: =IF( Tableau3[[#This Row],[Date d''expiration ]]>TODAY(),"Néant","Cas à justifier") -> Néant | I42: 30746 | J42: =YEARFRAC(I42,TODAY(),1) -> 42.504457 | K42: =YEARFRAC(I42,RG_DRH_S1_008!$E$4,1) -> 41.822045 | L42: =YEARFRAC(I42,RG_DRH_S1_008!$E$5,1) -> 42.822043 | M42: Conducteur de ligne | N42: Z2M, E1300, E1250, E1400, E1450 | O42: Casa-Kenitra, Casa-Tanger , Casa-Marrakech, Fès - Casa | P42: 45589 | Q42: Apte classe 1 | R42: =YEARFRAC(I42,P42,1) -> 40.635884 | S42: =IF(L42<40,"4",IF(L42<50,"3",IF(L42<55,IF(Tableau3[[#This Row],[Fonction]]="Conducteur de ligne","2","3"),"1"))) -> 3 | T42: =EDATE(P42, (12*S42)) -> 46684 | U42: 45463 | V42: FAVORABLE MAINT | W42: =YEARFRAC(I42,U42,1) -> 40.290932 | X42: =IF(L42<40,"4",IF(L42<55,"3",IF(Tableau3[[#This Row],[Fonction]]="conducteur de ligne","1","2"))) -> 3 | Y42: =EDATE(U42, (12*X42)) -> 46558 | Z42: 46176 | AA42: =IF(Tableau3[[#This Row],[Date prochaine évaluation]]> TODAY(),"Réussi","Examen expiré") -> Réussi | AB42: =EDATE(Z42, 12) -> 46541 | AC42: =EDATE(AA42, 12) -> #VALUE!
B43: BENAASI MOHAMMED | C43: 85469Z | D43: Kénitra | F43: =IF(Tableau3[[#This Row],[Date d''expiration ]]>TODAY()+31,"✅",IF(Tableau3[[#This Row],[Date d''expiration ]]> TODAY()+1, "⚠️","⛔️")) -> ✅ | G43: =MIN(T43,Y43,AB43) -> 46384 | H43: =IF( Tableau3[[#This Row],[Date d''expiration ]]>TODAY(),"Néant","Cas à justifier") -> Néant | I43: 30386 | J43: =YEARFRAC(I43,TODAY(),1) -> 43.49076 | K43: =YEARFRAC(I43,RG_DRH_S1_008!$E$4,1) -> 42.808353 | L43: =YEARFRAC(I43,RG_DRH_S1_008!$E$5,1) -> 43.80835 | M43: Conducteur de ligne | N43: E1450, E1400 | O43: Casa-Kenitra, Casa-Tanger , Casa-Marrakech, Fès - Casa | P43: 45785 | Q43: Apte classe 1 | R43: =YEARFRAC(I43,P43,1) -> 42.159493 | S43: =IF(L43<40,"4",IF(L43<50,"3",IF(L43<55,IF(Tableau3[[#This Row],[Fonction]]="Conducteur de ligne","2","3"),"1"))) -> 3 | T43: =EDATE(P43, (12*S43)) -> 46881 | U43: 45288 | V43: FAVORABLE MAINT | W43: =YEARFRAC(I43,U43,1) -> 40.800134 | X43: =IF(L43<40,"4",IF(L43<55,"3",IF(Tableau3[[#This Row],[Fonction]]="conducteur de ligne","1","2"))) -> 3 | Y43: =EDATE(U43, (12*X43)) -> 46384 | Z43: 46181 | AA43: =IF(Tableau3[[#This Row],[Date prochaine évaluation]]> TODAY(),"Réussi","Examen expiré") -> Réussi | AB43: =EDATE(Z43, 12) -> 46546 | AC43: =EDATE(AA43, 12) -> #VALUE!
...

Sheet Formation
B2: Registre des habilitations : Formation (CFT, DFT et EFT)
B4: L'habilitation est valable pour une durée supérieure à un mois. | C4: ✅ | D4: L'habilitation est valable pour une durée inférieure à un mois. | F4: ⚠️ | G4: L'habilitation est expirée. | H4: ⛔️
B6: Collaborateur | F6: La validité de l'habilitation | I6: Âge | M6: Périmètre d'habilitation | Q6: Aptitude physique (VM) | V6: Aptitude psychologique | AA6: Aptitude Professionnelle
B7: Nom / prénom | C7: Matricule | D7: Résidence | E7: Date d'autorisation | F7: Validité | G7: Date d'expiration | H7: Motif | I7: Date naissance | J7: Âge actuel | K7: Âge Fin 25 | L7: Âge Fin 26 | M7: Fonction | N7: Engin | O7: type de matériel | P7: Site | Q7: Dernière VM | R7: Résultat/Obs | S7: Âge_dernière VM | T7: Périodicité VM | U7: Date prochaine VM | V7: Dernier Psy | W7: Résultat/Obs | X7: Âge_dernier Psy | Y7: Périodicité Psy | Z7: Date prochain Psy | AA7: Dernière évaluation | AB7: Résultat /Obs | AC7: Date prochaine évaluation
B8: EL AMRAOUI MOHAMMED | C8: 38008Y | D8: Kénitra | F8: =IF(Tableau35[[#This Row],[Date d''expiration ]]>TODAY()+31,"✅",IF(Tableau35[[#This Row],[Date d''expiration ]]> TODAY()+1, "⚠️","⛔️")) -> ⛔️ | G8: =MIN(U8,Z8,AC8) -> 45638 | H8: Neant | I8: 24663 | J8: =YEARFRAC(I8,TODAY(),1) -> 59.15948 | K8: =YEARFRAC(I8,RG_DRH_S1_008!$E$4,1) -> 58.477077 | L8: =YEARFRAC(I8,RG_DRH_S1_008!$E$5,1) -> 59.47707 | M8: Chef Formation Trains | N8: E1450.E1400.Z2M.DM600.DH400.DH350 | O8: Matériel à Voyageurs | P8: Site Voyageurs Kénitra | Q8: 45932 | R8: Apte classe 2 | S8: =YEARFRAC(I8,Q8,1) -> 58.230673 | T8: =IF(Tableau35[[#This Row],[Âge Fin 26]]<40,"5",IF(Tableau35[[#This Row],[Âge Fin 26]]<50,"4",IF(Tableau35[[#This Row],[Âge Fin 26]]<55,"3","2"))) -> 2 | U8: =EDATE(Q8, (12*T8)) -> 46662 | V8: 45691 | W8: FAVORABLE MAINT | X8: =YEARFRAC(I8,V8,1) -> 57.570858 | Y8: =IF(Tableau35[[#This Row],[Âge Fin 26]]<40,"5",IF(Tableau35[[#This Row],[Âge Fin 26]]<55,"3","2")) -> 2 | Z8: =EDATE(V8, (12*Y8)) -> 46421 | AA8: 45272 | AB8: =IF(Tableau35[[#This Row],[Date prochaine évaluation]]> TODAY(),"Réussi","Examen expiré") -> Examen expiré | AC8: =EDATE(AA8, 12) -> 45638
B9: ZERIOUH MOHAMED | C9: 44004K | D9: Kénitra | F9: =IF(Tableau35[[#This Row],[Date d''expiration ]]>TODAY()+31,"✅",IF(Tableau35[[#This Row],[Date d''expiration ]]> TODAY()+1, "⚠️","⛔️")) -> ✅ | G9: =MIN(U9,Z9,AC9) -> 46491 | H9: =IF(Tableau35[[#This Row],[Date d''expiration ]]>TODAY(),"Néant","Cas à justifier") -> Néant | I9: 33199 | J9: =YEARFRAC(I9,TODAY(),1) -> 35.789848 | K9: =YEARFRAC(I9,RG_DRH_S1_008!$E$4,1) -> 35.107461 | L9: =YEARFRAC(I9,RG_DRH_S1_008!$E$5,1) -> 36.107444 | M9: Chef Formation Trains | N9: E1450.E1400.Z2M.DM600.DH400.DH350 | O9: Matériel à Voyageurs | P9: Site Voyageurs Kénitra | Q9: 44665 | R9: Apte classe 1 | S9: =YEARFRAC(I9,Q9,1) -> 31.392848 | T9: =IF(Tableau35[[#This Row],[Âge Fin 26]]<40,"5",IF(Tableau35[[#This Row],[Âge Fin 26]]<50,"4",IF(Tableau35[[#This Row],[Âge Fin 26]]<55,"3","2"))) -> 5 | U9: =EDATE(Q9, (12*T9)) -> 46491 | V9: 45812 | W9: FAVORABLE MAINT | X9: =YEARFRAC(I9,V9,1) -> 34.532512 | Y9: =IF(Tableau35[[#This Row],[Âge Fin 26]]<40,"5",IF(Tableau35[[#This Row],[Âge Fin 26]]<55,"3","2")) -> 5 | Z9: =EDATE(V9, (12*Y9)) -> 47638 | AA9: 46207 | AB9: =IF(Tableau35[[#This Row],[Date prochaine évaluation]]> TODAY(),"Réussi","Examen expiré") -> Réussi | AC9: =EDATE(AA9, 12) -> 46572
B10: OUGUI HAMZA | C10: 45892H | D10: Kénitra | F10: =IF(Tableau35[[#This Row],[Date d''expiration ]]>TODAY()+31,"✅",IF(Tableau35[[#This Row],[Date d''expiration ]]> TODAY()+1, "⚠️","⛔️")) -> ✅ | G10: =MIN(U10,Z10,AC10) -> 46415 | H10: =IF(Tableau35[[#This Row],[Date d''expiration ]]>TODAY(),"Néant","Cas à justifier") -> Néant | I10: 36550 | J10: =YEARFRAC(I10,TODAY(),1) -> 26.613973 | K10: =YEARFRAC(I10,RG_DRH_S1_008!$E$4,1) -> 25.931557 | L10: =YEARFRAC(I10,RG_DRH_S1_008!$E$5,1) -> 26.931555 | M10: Chef Formation Trains | N10: E1450.E1400.Z2M.DM600.DH400.DH350 | O10: Matériel à Voyageurs | P10: Site Voyageurs Kénitra | Q10: 44698 | R10: Apte classe 1 | S10: =YEARFRAC(I10,Q10,1) -> 22.307344 | T10: =IF(Tableau35[[#This Row],[Âge Fin 26]]<40,"5",IF(Tableau35[[#This Row],[Âge Fin 26]]<50,"4",IF(Tableau35[[#This Row],[Âge Fin 26]]<55,"3","2"))) -> 5 | U10: =EDATE(Q10, (12*T10)) -> 46524 | V10: 46239 | W10: FAVORABLE MAINT | X10: =YEARFRAC(I10,V10,1) -> 26.526364 | Y10: =IF(Tableau35[[#This Row],[Âge Fin 26]]<40,"5",IF(Tableau35[[#This Row],[Âge Fin 26]]<55,"3","2")) -> 5 | Z10: =EDATE(V10, (12*Y10)) -> 48065 | AA10: 46050 | AB10: =IF(Tableau35[[#This Row],[Date prochaine évaluation]]> TODAY(),"Réussi","Examen expiré") -> Réussi | AC10: =EDATE(AA10, 12) -> 46415
B11: LAABABID ABDELAALIM | C11: 46823R | D11: Kénitra | F11: =IF(Tableau35[[#This Row],[Date d''expiration ]]>TODAY()+31,"✅",IF(Tableau35[[#This Row],[Date d''expiration ]]> TODAY()+1, "⚠️","⛔️")) -> ⛔️ | G11: =MIN(U11,Z11,AC11) -> 46156 | H11: =IF(Tableau35[[#This Row],[Date d''expiration ]]>TODAY(),"Néant","Cas à justifier") -> Cas à justifier | I11: 36658 | J11: =YEARFRAC(I11,TODAY(),1) -> 26.318292 | K11: =YEARFRAC(I11,RG_DRH_S1_008!$E$4,1) -> 25.635885 | L11: =YEARFRAC(I11,RG_DRH_S1_008!$E$5,1) -> 26.635875 | M11: Chef Formation Trains | N11: E1450.E1400.Z2M.DM600.DH400.DH350 | O11: Matériel à Voyageurs | P11: Site Voyageurs Kénitra | Q11: 45540 | R11: Apte classe 1 | S11: =YEARFRAC(I11,Q11,1) -> 24.315594 | T11: =IF(Tableau35[[#This Row],[Âge Fin 26]]<40,"5",IF(Tableau35[[#This Row],[Âge Fin 26]]<50,"4",IF(Tableau35[[#This Row],[Âge Fin 26]]<55,"3","2"))) -> 5 | U11: =EDATE(Q11, (12*T11)) -> 47366 | V11: 44981 | W11: FAVORABLE MAINT | X11: =YEARFRAC(I11,V11,1) -> 22.787132 | Y11: =IF(Tableau35[[#This Row],[Âge Fin 26]]<40,"5",IF(Tableau35[[#This Row],[Âge Fin 26]]<55,"3","2")) -> 5 | Z11: =EDATE(V11, (12*Y11)) -> 46807 | AA11: 45791 | AB11: =IF(Tableau35[[#This Row],[Date prochaine évaluation]]> TODAY(),"Réussi","Examen expiré") -> Examen expiré | AC11: =EDATE(AA11, 12) -> 46156
B12: EL KHALFAOUI AYOUB | C12: 47614H | D12: Kénitra | F12: =IF(Tableau35[[#This Row],[Date d''expiration ]]>TODAY()+31,"✅",IF(Tableau35[[#This Row],[Date d''expiration ]]> TODAY()+1, "⚠️","⛔️")) -> ⛔️ | G12: =MIN(U12,Z12,AC12) -> 46267 | H12: =IF(Tableau35[[#This Row],[Date d''expiration ]]>TODAY(),"Néant","Cas à justifier") -> Cas à justifier | I12: 35637 | J12: =YEARFRAC(I12,TODAY(),1) -> 29.115634 | K12: =YEARFRAC(I12,RG_DRH_S1_008!$E$4,1) -> 28.433252 | L12: =YEARFRAC(I12,RG_DRH_S1_008!$E$5,1) -> 29.433239 | M12: Chef Formation Trains | N12: E1450.E1400.Z2M.DM600.DH400.DH350 | O12: Matériel à Voyageurs | P12: Site Voyageurs Kénitra | Q12: 45615 | R12: Apte classe 2 | S12: =YEARFRAC(I12,Q12,1) -> 27.318275 | T12: =IF(Tableau35[[#This Row],[Âge Fin 26]]<40,"5",IF(Tableau35[[#This Row],[Âge Fin 26]]<50,"4",IF(Tableau35[[#This Row],[Âge Fin 26]]<55,"3","2"))) -> 5 | U12: =EDATE(Q12, (12*T12)) -> 47441 | V12: 45355 | W12: FAVORABLE MAINT | X12: =YEARFRAC(I12,V12,1) -> 26.606434 | Y12: =IF(Tableau35[[#This Row],[Âge Fin 26]]<40,"5",IF(Tableau35[[#This Row],[Âge Fin 26]]<55,"3","2")) -> 5 | Z12: =EDATE(V12, (12*Y12)) -> 47181 | AA12: 45902 | AB12: =IF(Tableau35[[#This Row],[Date prochaine évaluation]]> TODAY(),"Réussi","Examen expiré") -> Examen expiré | AC12: =EDATE(AA12, 12) -> 46267
B13: JAMALI MOHAMMED | C13: 47622S | D13: Kénitra | F13: =IF(Tableau35[[#This Row],[Date d''expiration ]]>TODAY()+31,"✅",IF(Tableau35[[#This Row],[Date d''expiration ]]> TODAY()+1, "⚠️","⛔️")) -> ⛔️ | G13: =MIN(U13,Z13,AC13) -> 46267 | H13: =IF(Tableau35[[#This Row],[Date d''expiration ]]>TODAY(),"Néant","Cas à justifier") -> Cas à justifier | I13: 36951 | J13: =YEARFRAC(I13,TODAY(),1) -> 25.518113 | K13: =YEARFRAC(I13,RG_DRH_S1_008!$E$4,1) -> 24.835724 | L13: =YEARFRAC(I13,RG_DRH_S1_008!$E$5,1) -> 25.83572 | M13: Chef Formation Trains | N13: E1450.E1400.Z2M.DM600.DH400.DH350 | O13: Matériel à Voyageurs | P13: Site Voyageurs Kénitra | Q13: 45616 | R13: Apte classe 1 | S13: =YEARFRAC(I13,Q13,1) -> 23.723477 | T13: =IF(Tableau35[[#This Row],[Âge Fin 26]]<40,"5",IF(Tableau35[[#This Row],[Âge Fin 26]]<50,"4",IF(Tableau35[[#This Row],[Âge Fin 26]]<55,"3","2"))) -> 5 | U13: =EDATE(Q13, (12*T13)) -> 47442 | V13: 45357 | W13: FAVORABLE MAINT | X13: =YEARFRAC(I13,V13,1) -> 23.014374 | Y13: =IF(Tableau35[[#This Row],[Âge Fin 26]]<40,"5",IF(Tableau35[[#This Row],[Âge Fin 26]]<55,"3","2")) -> 5 | Z13: =EDATE(V13, (12*Y13)) -> 47183 | AA13: 45902 | AB13: =IF(Tableau35[[#This Row],[Date prochaine évaluation]]> TODAY(),"Réussi","Examen expiré") -> Examen expiré | AC13: =EDATE(AA13, 12) -> 46267
B14: BOUGNINE MOSTAFA | C14: 47607A | D14: Kénitra | F14: =IF(Tableau35[[#This Row],[Date d''expiration ]]>TODAY()+31,"✅",IF(Tableau35[[#This Row],[Date d''expiration ]]> TODAY()+1, "⚠️","⛔️")) -> ⛔️ | G14: =MIN(U14,Z14,AC14) -> 46267 | H14: =IF(Tableau35[[#This Row],[Date d''expiration ]]>TODAY(),"Néant","Cas à justifier") -> Cas à justifier | I14: 34662 | J14: =YEARFRAC(I14,TODAY(),1) -> 31.784369 | K14: =YEARFRAC(I14,RG_DRH_S1_008!$E$4,1) -> 31.101985 | L14: =YEARFRAC(I14,RG_DRH_S1_008!$E$5,1) -> 32.101966 | M14: Chef Formation Trains | N14: E1450.E1400.Z2M.DM600.DH400.DH350 | O14: Matériel à Voyageurs | P14: Site Voyageurs Kénitra | Q14: 45621 | R14: Apte classe 2 | S14: =YEARFRAC(I14,Q14,1) -> 30.003444 | T14: =IF(Tableau35[[#This Row],[Âge Fin 26]]<40,"5",IF(Tableau35[[#This Row],[Âge Fin 26]]<50,"4",IF(Tableau35[[#This Row],[Âge Fin 26]]<55,"3","2"))) -> 5 | U14: =EDATE(Q14, (12*T14)) -> 47447 | V14: 45356 | W14: FAVORABLE MAINT | X14: =YEARFRAC(I14,V14,1) -> 29.27793 | Y14: =IF(Tableau35[[#This Row],[Âge Fin 26]]<40,"5",IF(Tableau35[[#This Row],[Âge Fin 26]]<55,"3","2")) -> 5 | Z14: =EDATE(V14, (12*Y14)) -> 47182 | AA14: 45902 | AB14: =IF(Tableau35[[#This Row],[Date prochaine évaluation]]> TODAY(),"Réussi","Examen expiré") -> Examen expiré | AC14: =EDATE(AA14, 12) -> 46267
B15: CHTIOUI MOHAMMED | C15: 44867M | D15: Kénitra | F15: =IF(Tableau35[[#This Row],[Date d''expiration ]]>TODAY()+31,"✅",IF(Tableau35[[#This Row],[Date d''expiration ]]> TODAY()+1, "⚠️","⛔️")) -> ✅ | G15: =MIN(U15,Z15,AC15) -> 46333 | H15: =IF(Tableau35[[#This Row],[Date d''expiration ]]>TODAY(),"Néant","Cas à justifier") -> Néant | I15: 34693 | J15: =YEARFRAC(I15,TODAY(),1) -> 31.699494 | K15: =YEARFRAC(I15,RG_DRH_S1_008!$E$4,1) -> 31.017112 | L15: =YEARFRAC(I15,RG_DRH_S1_008!$E$5,1) -> 32.017091 | M15: Encadrant Formation Trains | N15: E1450.E1400.Z2M.DM600.DH400.DH350 | O15: Matériel à Voyageurs | P15: Site Voyageurs Kénitra | Q15: 45334 | R15: Apte classe 1 | S15: =YEARFRAC(I15,Q15,1) -> 29.132827 | T15: =IF(Tableau35[[#This Row],[Âge Fin 26]]<40,"5",IF(Tableau35[[#This Row],[Âge Fin 26]]<50,"4",IF(Tableau35[[#This Row],[Âge Fin 26]]<55,"3","2"))) -> 5 | U15: =EDATE(Q15, (12*T15)) -> 47161 | V15: 44949 | W15: FAVORABLE MAINT | X15: =YEARFRAC(I15,V15,1) -> 28.080679 | Y15: =IF(Tableau35[[#This Row],[Âge Fin 26]]<40,"5",IF(Tableau35[[#This Row],[Âge Fin 26]]<55,"3","2")) -> 5 | Z15: =EDATE(V15, (12*Y15)) -> 46775 | AA15: 45968 | AB15: =IF(Tableau35[[#This Row],[Date prochaine évaluation]]> TODAY(),"Réussi","Examen expiré") -> Réussi | AC15: =EDATE(AA15, 12) -> 46333
B16: DOUDOU RIDOUANE | C16: 44869P | D16: Kénitra | F16: =IF(Tableau35[[#This Row],[Date d''expiration ]]>TODAY()+31,"✅",IF(Tableau35[[#This Row],[Date d''expiration ]]> TODAY()+1, "⚠️","⛔️")) -> ✅ | G16: =MIN(U16,Z16,AC16) -> 46333 | H16: =IF(Tableau35[[#This Row],[Date d''expiration ]]>TODAY(),"Néant","Cas à justifier") -> Néant | I16: 34380 | J16: =YEARFRAC(I16,TODAY(),1) -> 32.556459 | K16: =YEARFRAC(I16,RG_DRH_S1_008!$E$4,1) -> 31.874059 | L16: =YEARFRAC(I16,RG_DRH_S1_008!$E$5,1) -> 32.874056 | M16: Encadrant Formation Trains | N16: E1450.E1400.Z2M.DM600.DH400.DH351 | O16: Matériel à Voyageurs | P16: Site Voyageurs Kénitra | Q16: 45336 | R16: Apte classe 1 | S16: =YEARFRAC(I16,Q16,1) -> 29.995231 | T16: =IF(Tableau35[[#This Row],[Âge Fin 26]]<40,"5",IF(Tableau35[[#This Row],[Âge Fin 26]]<50,"4",IF(Tableau35[[#This Row],[Âge Fin 26]]<55,"3","2"))) -> 5 | U16: =EDATE(Q16, (12*T16)) -> 47163 | V16: 44950 | W16: FAVORABLE MAINT | X16: =YEARFRAC(I16,V16,1) -> 28.940403 | Y16: =IF(Tableau35[[#This Row],[Âge Fin 26]]<40,"5",IF(Tableau35[[#This Row],[Âge Fin 26]]<55,"3","2")) -> 5 | Z16: =EDATE(V16, (12*Y16)) -> 46776 | AA16: 45968 | AB16: =IF(Tableau35[[#This Row],[Date prochaine évaluation]]> TODAY(),"Réussi","Examen expiré") -> Réussi | AC16: =EDATE(AA16, 12) -> 46333
B17: EL OUEDRHIRI ACHRAF | C17: 46960E | D17: Kénitra | F17: =IF(Tableau35[[#This Row],[Date d''expiration ]]>TODAY()+31,"✅",IF(Tableau35[[#This Row],[Date d''expiration ]]> TODAY()+1, "⚠️","⛔️")) -> ⚠️ | G17: =MIN(U17,Z17,AC17) -> 46283 | H17: =IF(Tableau35[[#This Row],[Date d''expiration ]]>TODAY(),"Néant","Cas à justifier") -> Néant | I17: 37565 | J17: =YEARFRAC(I17,TODAY(),1) -> 23.836382 | K17: =YEARFRAC(I17,RG_DRH_S1_008!$E$4,1) -> 23.154004 | L17: =YEARFRAC(I17,RG_DRH_S1_008!$E$5,1) -> 24.153981 | M17: Encadrant Formation Trains | O17: Matériel à Voyageurs | P17: Site Voyageurs Kénitra | Q17: 45642 | R17: Apte classe 2 | S17: =YEARFRAC(I17,Q17,1) -> 22.112963 | T17: =IF(Tableau35[[#This Row],[Âge Fin 26]]<40,"5",IF(Tableau35[[#This Row],[Âge Fin 26]]<50,"4",IF(Tableau35[[#This Row],[Âge Fin 26]]<55,"3","2"))) -> 5 | U17: =EDATE(Q17, (12*T17)) -> 47468 | V17: 45786 | W17: FAVORABLE MAINT | X17: =YEARFRAC(I17,V17,1) -> 22.507871 | Y17: =IF(Tableau35[[#This Row],[Âge Fin 26]]<40,"5",IF(Tableau35[[#This Row],[Âge Fin 26]]<55,"3","2")) -> 5 | Z17: =EDATE(V17, (12*Y17)) -> 47612 | AA17: 45918 | AB17: =IF(Tableau35[[#This Row],[Date prochaine évaluation]]> TODAY(),"Réussi","Examen expiré") -> Réussi | AC17: =EDATE(AA17, 12) -> 46283
